Workbook

Sheet Instruções
A2: INSTRUÇÕES
A3: 1 | B3: Antes de começar, faça a sua cópia desta planilha. Vá até "arquivo", "fazer uma cópia", salve o documento no seu computador e pronto! Caso queira fazer mais de um PDI, faça uma cópia dessa planilha e a utilize para a(s) outra(s) pessoa(s), pois cada planilha serve para um PDI. Atenção, só preencha as células em cinza nas abas seguintes!
A4: 2 | B4: Na aba "Análise e Planejamento", na parte inicial, "Análise de Avaliação de Desempenho", foque em discutir com a pessoa para a qual você está fazendo o PDI (seja você do RH, líder ou mentor dessa pessoa) o resultado da avaliação de desempenho dela. Caso não exista uma avaliação de desempenho pré-PDI, não há problema, busque insumos com as pessoas que trabalham próximo a ela, com seus líderes e com a própria pessoa sobre seus pontos fortes e pontos a desenvolver.
A5: 3 | B5: Na aba "Análise e Planejamento", na parte de "Priorizando Pontos a Desenvolver", preencha a matriz GUT para definir qual será o foco do PDI e os pontos a desenvolver secundários. Após preencher a matriz, defina os indicadores que servirão para mensurar se a pessoa está progredindo ou não, bem como as metas para cada um dos indicadores definidos.
B6: Matriz GUT - O que é? - Item 8
A7: 4 | B7: Na aba "Resultados Obtidos", preencha apenas as células em cinza das colunas E e F. As demais células e gráficos são atualizados automaticamente. Utilize essa aba para acompanhar ao longo do próximo período se os resultados obtidos pela pessoa no período estão de acordo com as metas.

Sheet Análise e Planejamento
A1: ANÁLISE DE AVALIAÇÃO DE DESEMPENHO
A4: Quais foram os pontos fortes levantados ? | D4: Caso não tenha uma avaliação de desempenho prévia, discuta com a pessoa, com seu(s) líder(es) direto(s) e pessoas que trabalham próximo a ela quais são seus pontos fortes e seus pontos a desenvolver. | G4: Quais foram os pontos a desenvolver levantados?
A5: 1 | G5: 1
A6: 2 | G6: 2
A7: 3 | G7: 3
A8: 4 | G8: 4
A9: 5 | G9: 5
A13: PRIORIZANDO PONTOS A DESENVOLVER
A14: Matriz GUT (Gravidade, Urgência, Tendência)
A15: # | B15: Multiplicação (GxUxT) | C15: Pontos a Desenvolver | D15: Gravidade | E15: Urgência | F15: Tendência | G15: # | H15: Qual Ponto a Desenvolver Priorizar?
A16: 1 | B16: =D16*E16*F16 -> 0 | C16: =H5 | G16: {=SORT(B16:C20,1,FALSE())} -> 0
A17: 2 | B17: =D17*E17*F17 -> 0 | C17: =H6 | G17: 0
A18: 3 | B18: =D18*E18*F18 -> 0 | C18: =H7 | G18: 0
A19: 4 | B19: =D19*E19*F19 -> 0 | C19: =H8 | G19: 0
A20: 5 | B20: =D20*E20*F20 -> 0 | C20: =H9 | G20: 0
B24: OBJETIVO PRINCIPAL DO PDI | D24: INDICADOR(ES) QUE MEDE(M) SE VOCÊ ESTÁ SE APROXIMANDO OU NÃO DE CONQUISTAR ESSE OBJETIVO | H24: META AO FINAL DO PERÍODO
B25: =H16
B29: OBJETIVOS SECUNDÁRIOS DO PDI | D29: INDICADORES QUE MEDE(M) SE VOCÊ ESTÁ SE APROXIMANDO OU NÃO DE CONQUISTAR ESSE OBJETIVO | H29: META AO FINAL DO PERÍODO
B30: =H17
B31: =H18
B32: =H19
B33: =H20
B35: EXEMPLO
B36: OBJETIVO PRINCIPAL DO PDI | D36: INDICADOR(ES) QUE MEDE(M) SE VOCÊ ESTÁ SE APROXIMANDO OU NÃO DE CONQUISTAR ESSE OBJETIVO | H36: META AO FINAL DO PERÍODO
B37: Sair da minha zona de conforto | D37: Começar projetos fora do meu padrão de trabalho | H37: 2 projetos
B38: OBJETIVOS SECUNDÁRIOS DO PDI | D38: INDICADORES QUE MEDE(M) SE VOCÊ ESTÁ SE APROXIMANDO OU NÃO DE CONQUISTAR ESSE OBJETIVO | H38: META AO FINAL DO PERÍODO
B39: Me comunicar melhor com as pessoas | D39: Número de pessoas diferentes que conversei pelo menos 15 minutos na empresa e que nunca havia conversado | H39: 10 pessoas
B40: ... | D40: ... | H40: ...

Sheet Resultados Obtidos
A1: RESULTADOS OBTIDOS AO LONGO DO ANO
A2: NÃO ALTERE AS COLUNAS EM BRANCO - ELAS SÃO AUTOMATICAMENTE PREENCHIDAS APÓS A DEFINIÇÃO DE OBJETIVOS NA ABA "ANÁLISE E PLANEJAMENTO" | E2: PREENCHA NESSA COLUNA AS METAS DEFINIDAS POR VOCÊ E, TAMBÉM, RESULTADOS OBTIDOS AO LONGO DO ANO PARA OS INDICADORES DEFINIDOS PREVIAMENTE | G2: APÓS PREENCHER AS COLUNAS "E" E "F" COM AS METAS E RESULTADOS OBTIDOS OS GRÁFICOS ABAIXO SERÃO ATUALIZADOS AUTOMATICAMENTE
A3: Mês | B3: Tipo de Objetivo | C3: Objetivo | D3: Indicador | E3: Meta | F3: Resultado Obtido
A4: 44562 | B4: Principal | C4: ='Análise e Planejamento'!$B$25 | D4: ='Análise e Planejamento'!$D$25
A5: 44593 | B5: Principal | C5: ='Análise e Planejamento'!$B$25 | D5: ='Análise e Planejamento'!$D$25
A6: 44621 | B6: Principal | C6: ='Análise e Planejamento'!$B$25 | D6: ='Análise e Planejamento'!$D$25
A7: 44652 | B7: Principal | C7: ='Análise e Planejamento'!$B$25 | D7: ='Análise e Planejamento'!$D$25
A8: 44682 | B8: Principal | C8: ='Análise e Planejamento'!$B$25 | D8: ='Análise e Planejamento'!$D$25
A9: 44713 | B9: Principal | C9: ='Análise e Planejamento'!$B$25 | D9: ='Análise e Planejamento'!$D$25
A10: 44743 | B10: Principal | C10: ='Análise e Planejamento'!$B$25 | D10: ='Análise e Planejamento'!$D$25
A11: 44774 | B11: Principal | C11: ='Análise e Planejamento'!$B$25 | D11: ='Análise e Planejamento'!$D$25
A12: 44805 | B12: Principal | C12: ='Análise e Planejamento'!$B$25 | D12: ='Análise e Planejamento'!$D$25
A13: 44835 | B13: Principal | C13: ='Análise e Planejamento'!$B$25 | D13: ='Análise e Planejamento'!$D$25
A14: 44866 | B14: Principal | C14: ='Análise e Planejamento'!$B$25 | D14: ='Análise e Planejamento'!$D$25
A15: 44896 | B15: Principal | C15: ='Análise e Planejamento'!$B$25 | D15: ='Análise e Planejamento'!$D$25
A16: Mês | B16: Tipo de Objetivo | C16: Objetivo | D16: Indicador | E16: Meta | F16: Resultado Obtido
A17: 44562 | B17: Secundário | C17: ='Análise e Planejamento'!$B$30 | D17: ='Análise e Planejamento'!$D$30
A18: 44593 | B18: Secundário | C18: ='Análise e Planejamento'!$B$30 | D18: ='Análise e Planejamento'!$D$30
A19: 44621 | B19: Secundário | C19: ='Análise e Planejamento'!$B$30 | D19: ='Análise e Planejamento'!$D$30
A20: 44652 | B20: Secundário | C20: ='Análise e Planejamento'!$B$30 | D20: ='Análise e Planejamento'!$D$30
A21: 44682 | B21: Secundário | C21: ='Análise e Planejamento'!$B$30 | D21: ='Análise e Planejamento'!$D$30
A22: 44713 | B22: Secundário | C22: ='Análise e Planejamento'!$B$30 | D22: ='Análise e Planejamento'!$D$30
A23: 44743 | B23: Secundário | C23: ='Análise e Planejamento'!$B$30 | D23: ='Análise e Planejamento'!$D$30
A24: 44774 | B24: Secundário | C24: ='Análise e Planejamento'!$B$30 | D24: ='Análise e Planejamento'!$D$30
A25: 44805 | B25: Secundário | C25: ='Análise e Planejamento'!$B$30 | D25: ='Análise e Planejamento'!$D$30
A26: 44835 | B26: Secundário | C26: ='Análise e Planejamento'!$B$30 | D26: ='Análise e Planejamento'!$D$30
A27: 44866 | B27: Secundário | C27: ='Análise e Planejamento'!$B$30 | D27: ='Análise e Planejamento'!$D$30
A28: 44896 | B28: Secundário | C28: ='Análise e Planejamento'!$B$30 | D28: ='Análise e Planejamento'!$D$30
A29: Mês | B29: Tipo de Objetivo | C29: Objetivo | D29: Indicador | E29: Meta | F29: Resultado Obtido
A30: 44562 | B30: Secundário | C30: ='Análise e Planejamento'!$B$31 | D30: ='Análise e Planejamento'!$D$31
A31: 44593 | B31: Secundário | C31: ='Análise e Planejamento'!$B$31 | D31: ='Análise e Planejamento'!$D$31
A32: 44621 | B32: Secundário | C32: ='Análise e Planejamento'!$B$31 | D32: ='Análise e Planejamento'!$D$31
A33: 44652 | B33: Secundário | C33: ='Análise e Planejamento'!$B$31 | D33: ='Análise e Planejamento'!$D$31
A34: 44682 | B34: Secundário | C34: ='Análise e Planejamento'!$B$31 | D34: ='Análise e Planejamento'!$D$31
A35: 44713 | B35: Secundário | C35: ='Análise e Planejamento'!$B$31 | D35: ='Análise e Planejamento'!$D$31
A36: 44743 | B36: Secundário | C36: ='Análise e Planejamento'!$B$31 | D36: ='Análise e Planejamento'!$D$31
A37: 44774 | B37: Secundário | C37: ='Análise e Planejamento'!$B$31 | D37: ='Análise e Planejamento'!$D$31
A38: 44805 | B38: Secundário | C38: ='Análise e Planejamento'!$B$31 | D38: ='Análise e Planejamento'!$D$31
A39: 44835 | B39: Secundário | C39: ='Análise e Planejamento'!$B$31 | D39: ='Análise e Planejamento'!$D$31
A40: 44866 | B40: Secundário | C40: ='Análise e Planejamento'!$B$31 | D40: ='Análise e Planejamento'!$D$31
...

Sheet Dê o Próximo Passo
A1: DESENVOLVA SEUS COLABORADORES
A3: Já pensou gerar todos esses gráficos, metas e PDIs de maneira automatizada?
B5: Experimente grátis nossa plataforma e dê o próximo passo para tornar o RH da sua empresa mais eficiente!
C7: Quero Tornar Meu RH Eficiente!
